File: examples/vms/irregular.vms
VAMAS Surface Chemical Analysis Standard Data Transfer Format 1988 May 4
Not Specified
Not Specified
Not Specified
Not Specified
5
Casa Info Follows CasaXPS Version 2.3.26PR1.0
0
Created by SpecsLab Prodigy, Version 4.100.1-r111001
SourceAnalyserAngle: Not Specified
CasaRowLabel:1 as-loaded
NORM
IRREGULAR
1
1
Value
d
0
0
0
0
1
Counts per Second
1 as-loaded
0
0
0
0
0
0
0
6
Casa Info Follows
0
0
0
0

XPS
0
Al
1486.61
1e+037
1e+037
1e+037
1e+037
1e+037
FAT
1e+037
1e+037
1e+037
1e+037
1e+037
1e+037
1e+037
1e+037
Survey

-1
3
Kinetic Energy
eV
Intensity
d
transmission
d
pulse counting
1
1
1e+037
1e+037
1e+037
1e+037
2
MFP Exponent
d
0
ESCAPE DEPTH TYPE
d
1
1
0
15598.7
15867.9
15651.5
15321.3
15793.4
15662
15599
15758.9
15681.7
15968.1
15844.6
15328.3
15541
15355.9
15531.3
15831.1
15628.4
15643.4
15649.2
15508.5
16168.7
16783.7
16696.5
17242
16225.4
16518.6
16381.9
16956.2
16503.2
17074.8
16608.9
16689.8
16261.6
16260.5
15986.7
15943.1
15576.2
15749.3
15307.1
15088.5
15583.9
15913.9
17185.3
17381.4
20956.8
26719.6
27570.7
22744.5
17508.6
15654.7
15118.7
15568.8
15345.7
15303
14938
15054.6
14976.5
15205
15306.2
15772.5
15744.1
15599.9
15973.4
15693.5
15909.2
16198.6
15966.9
15489.1
16474.9
15956.1
16501.6
15931.6
16115.7
16611.5
16061
16121.6
16202.9
16392.4
16503.7
16364.4
16383.3
15654.5
16709.3
16583.1
17054.4
16442.2
16428.8
16359.6
17035.9
16781.8
16532.9
16559.9
17396.7
17337.8
16964.5
17236.6
17187.5
17685.7
17413.9
17348.1
17745.6
17594.6
16802.7
17579.8
17782.9
18013.3
18298.8
18710.3
19254
18792.1
18473.2
18138.4
18382
18782.5
18880.3
18841.1
19294.1
19521.4
19505.7
19003.9
18726.7
19079.4
19667.5
19860.6
19563
18944.9
19116.6
19366.5
19505.1
19660.1
19174.2
19440.8
18765.7
19529.4
19357.7
19126.9
19879
19197.5
18743
19303.7
18895.3
18912.6
19686.7
20311.5
20127.5
20015.3
19671.3
20388.9
20034.7
19391.1
20300.1
21079.8
20574.4
20595.9
20473.3
20257.8
20594.2
21018
20826.8
20919.6
21146.1
20211.1
20873.9
21184.1
20921.1
20697.5
21410.1
20987.3
21123.2
21283.8
21746.4
22075.1
21570
21459.8
21401.2
21486.6
21931.1
21588.9
21547.3
23607.3
22903.4
22515.3
22090.6
21863
22432.8
23020.4
22759.1
23162.8
22785.6
22876.4
23135.4
23241.3
23401.4
23775.4
23535.7
23399.7
23587.6
23859.4
23837.4
23578.4
23574.6
23347.3
23557.3
23525.4
23911.9
23944.1
24266.8
24470.3
24506
24284
24114.6
24776.2
24734.3
24520.9
24584.1
25100.2
24669.4
25163.5
24937.1
25585.9
25144.7
25014.5
25424.6
25447.9
25640.2
26136.4
25730.6
26115.1
25993.9
26140.3
26458.3
25692.8
25948.6
26384.9
26150.8
26184
26887.5
27048.6
26457.8
26742.6
26680.6
26872.7
27118.8
27491.5
26834.9
27169.7
27231.8
27885
27614.6
27740.6
27574.8
27769.5
27314.5
28164.6
28215.2
27772.4
27946.3
28072
28986.1
28640.9
27931.4
27800.6
29132.5
28665.1
28725.3
29136.3
29238.4
29365.2
29056.3
29495.9
28955.4
29597
29193.9
29321.1
29775.9
29377.4
29529.6
29828.1
30018.2
29834
29996.3
30373.1
30314.6
31086.5
30178
30253.2
30820.5
30735
31271
31323.7
30857.3
31076.5
30252.6
31432.3
31016
32185.6
31861.4
31905.9
32140.4
31882.5
31804.1
32339.6
31953.6
32897.1
32456.5
32561.5
32865.1
32733.6
32345.2
32541.6
33078.3
32882.7
32824.1
32145.7
33879.3
33944.5
33463.8
33995.7
34321.7
33712.2
33822.9
35198.5
34655.7
34811.3
34009.6
34859
35005.1
34346.9
34454.5
35311.3
36074.3
36582.6
36478
36448.4
36802.7
37718.8
37531.8
36481.2
36675.2
36365.3
36290.3
36313.8
36661.6
37912.6
37630.1
37773.1
37597.9
38116.1
38829.8
39484.7
38626
39142.2
40090.2
39201.1
39574.7
38654.2
37852.7
38725.2
37536.5
38446
38553.7
37948.7
38602.9
37477.9
37154.9
37456.5
38694.4
39504.9
39709.5
40968.1
42570.4
44598.6
46921.3
47219.7
44644
42621.2
41423.9
40569.1
39280.1
38828.2
38663.8
37253.6
37653.3
37098.3
35628.9
36215.5
35974.2
35966.6
36380.7
36111.9
35791
36429.6
35897.4
35974
35544.8
35471.6
36427.2
36693.3
36934.2
36730.8
36751.1
35881.9
36926.7
37109.6
36861
37605.2
37078.4
37794.9
37610.4
37185.9
36840.6
37486.6
38197.9
38255.4
37829.5
38162.7
38173.4
37677.9
38357.6
38313.5
38460.4
38614.9
38816.5
38655.6
38574.5
38757.5
39066.8
39293.6
39082.4
38439.1
39090.5
38152.9
38546.3
38729.4
39550
39425
39291.3
39660
39880.6
39459.2
40366.3
39404.3
39114
39442.1
39894.8
40594.5
41142
41314.5
40379.4
40518.3
40805.8
40031.3
40935.1
41727.4
41213.8
40366.5
39954.5
40601.8
41550.4
41174.2
39908.5
40004.1
40413.5
38703.8
37789.9
37104.1
37906
38442
38213.2
38043.7
38022.1
37336.4
37188.2
37037.1
37581.6
37433.9
37219.2
37174.9
36637.6
37304.1
38202.2
37762.2
37774.4
37669.5
37697.1
38054.5
38066.4
38224
37840
38640.1
38021.2
37930.2
38559.7
38650.8
39697.5
39652.1
39516
39685.8
39936.1
40013.3
39355
39828.9
40402.7
40237.4
39118.1
39216
40227.9
40883.7
40411.3
40176.1
39271.9
38728.6
38762.4
38124.8
38105.2
37059.5
36613.2
35633.9
35011.2
34671.8
34094
34108.6
33420.5
33424.4
33410.8
33088.8
32447.9
32709.7
33042.6
33160.9
32475
32694.2
33356.6
32765.8
32989.5
33519.9
33337.6
32959.6
33471.2
33635.7
34246.7
33536.4
33207
33850
34221.8
34150.6
33819.6
34058.2
34473.3
34049.1
33899.6
34278.1
32797.2
33498.7
33890.1
33946.7
34235.1
35156.4
35035.1
35841.3
35701.8
36570.7
36075.6
36441.3
37434.5
37228.9
37006.4
36580.6
35991.7
35388.6
35170.2
35057.6
33893.8
32926.3
32694.2
33807.6
34488.3
34494.1
33890.6
33283.8
33660.7
33621.6
33323.5
33790.5
32614.5
32874.5
32554.7
32398.9
33327.5
32870.3
32982
33512.6
33100.5
33131.8
33334.3
32653.9
33982.8
33002.2
34189.1
33936.1
33454.2
33577.4
34217.1
34104.8
34752.2
34329.4
35765.6
34927.8
34767.5
34605.9
33289.9
34213.2
34434
34758.7
35532.1
36253.6
36049.4
37016.7
36226
36693.6
36628
36425.6
36881.5
37754.5
39094.9
39594.6
38731.3
38004.7
36773.6
34402.9
34239.4
33477
33150.5
33271.1
34049.5
34550.4
36645.3
39476.9
41438.5
40153.4
38074.8
33979.1
28033
24923.7
22677.4
22298.1
21216.5
21232.3
21897.1
21911
21791.9
21148.8
21907
21630.1
21832.8
21832.1
21321.1
21291.8
21761.1
21710.7
21849.7
21955.4
22421.9
22618.3
22598.5
22553.8
22017.1
22553.9
22201.3
21853.8
22413.4
22045.8
22473.1
22395.6
22614.9
22934.8
22728.8
22716.2
22215.3
23144.3
22969.7
23106.9
22979.1
22954.4
23272.2
22869.9
22656.1
23237.1
23494.1
22487.2
23008
22590.5
22804.9
23743.4
23271.9
23908.5
24016.9
23802
24074.2
23750.9
23729.7
23353.4
23673.5
23816.2
23586.7
23255
23785.1
24017.7
23702.4
24006.4
23742.9
24131.1
24420.7
24073.6
23434.9
23902.9
24731.2
24888.2
24476.1
24263.5
23900.7
24634.5
24252.4
25344.1
24700.1
24738.9
24833.9
24472.7
25037.1
24872.1
25410.3
25543.3
25483
25342
25642.3
25455.6
25806.4
25269.6
26298.9
25984.2
26255.3
25798.5
25474.2
25671.2
26107.7
26169
26033.8
25963.1
25735.6
26018
26206.8
26436.4
26345.9
26485.8
26141.4
26645.3
26401.1
26494.7
26203.4
26841.3
27708.6
27401.7
27456.4
27491.5
26847.6
26983.5
26921
26357.8
26796.5
27575.9
27468.2
27363.7
27297.7
27563.5
27779.7
27677.8
28141.3
28133.8
28335.1
28446.5
28001.8
28340.7
28912
29112.9
28637.3
27832.9
28025.4
28725.8
28315.6
28760.2
28883.4
29056.2
30108.1
30619.1
31800
33085.8
31594
31707.6
31263.6
29989.7
29151.5
29248.3
27126.8
27595.6
26335.8
26011.1
26104.7
25259.5
24843.6
24253.4
24451.8
24533
23436.6
24577
25820.3
28830.2
35099
49171.7
68714.3
79097.2
63369.1
36418.1
24477.6
21452.6
21341.4
20550.5
20585.8
21439.9
21296.6
21464.1
21243.4
21958.9
21651.9
21251.3
21762.7
21866.1
21384
21062.2
21850.7
21705.8
21608.4
21938.1
21455.8
21298
22211.5
22462.1
22093.8
21722.9
21844
22113.1
22282.1
22340.2
21911.6
22846.7
22079.6
21749.2
22123
22648.3
22194.2
22296.6
22835.1
22514.9
22009.4
22251.5
22409.7
22631
22113.2
22370.1
22395
23215.4
22945.3
23343.9
22369.9
22478.9
22746
22736.6
22485.4
23013.7
23706.2
23086.3
23017.2
23209.4
23451.7
24166.6
22915.4
23518.9
23553.3
23027.4
23705.6
23561.1
22853.4
23333
23702.3
23820.9
24149.8
24484.6
24406
23817.5
23419.5
23855.4
24184.2
24460.5
24046.9
24804
24239
24994.1
24487.4
24284.1
24448.8
24369.4
24333.4
24741.1
24243.3
24108.4
23780.5
24408
25272.2
24374.8
25479.8
24948.2
24863.8
24953.7
24860.1
24829.9
25815.3
25317.1
25869.6
26374.9
25671.9
26598.3
25424.2
26389.9
25475.4
25417.8
25805.4
25397.3
25498.9
25605.6
26194.3
26289.5
27224.6
26943.4
27404.8
27351.3
27300.4
27027.1
27231.4
27314.4
27434.5
27731.2
27398.2
27873
27358.1
27763.4
26819.7
26918.7
27615.9
27665.8
27777
28002.4
28241
27928.4
28587
29583.7
31229.1
33027.1
32668.5
31457.8
29731.6
29033.5
28839.9
29130.9
29390.3
28414.1
28991.1
29419.4
30099.2
29966.2
29322.1
28557.8
28303.2
28100.4
28284.8
28291.9
28384.8
28811.5
28849.7
28415.1
27943.8
28015.3
28593.2
28486
28903.2
28669.5
29885.3
30651.9
33538
40620.5
46163.1
48538.9
44908.7
37659.1
33003.1
29700.4
27945.5
27027.7
27870.6
27738.2
27647.1
27768.2
28494
30488.6
32851
35017.6
33298.9
30498.9
29861.1
29681.1
31073.1
31084
31298.8
31979.5
32527.9
31531.3
29697.4
29036.1
28067.9
26307.4
25255.5
24475.3
24957.3
24392.6
23205.6
22703.9
21890
21464
21459.7
24813
29234.9
33361.8
34971
38778.9
56391.1
85066.3
108366
96061
57359.8
29576.8
18228.3
13167.2
10857.9
9705
9261.49
8851.94
8621
7997.02
8076.53
7905.56
8018.22
8412.77
8531.77
9108.74
10421.1
12445.3
15800.5
14773.9
10951.6
8846.79
8143.72
7917.12
7438.45
7530.34
7350.1
7004.11
7168.32
7166.58
7154.84
7215.96
7476.36
7102.79
6973.13
7001.84
7195.88
7598.77
7606.59
7744.39
7207.57
7521.6
7409.5
7447.67
7288.99
7075.86
6979.76
6882.51
7137.34
6877.87
6508.49
7056.12
7229.9
7197.57
6896.92
6680.31
6904.96
7820.09
7853.14
8852.12
9221.77
9035.21
8808.02
7796.19
7510.4
7078.66
7047.54
6450.32
6911.09
7161.91
6939.09
6644.48
6939.13
7016.25
6554.99
6544.45
6745.67
6625.13
6850.18
6539.53
6533.73
6585.06
6827.85
6627.73
6388.73
6685.38
6876.57
6664.19
6384.56
6587.83
6921.75
6788.45
6671.56
6818.97
6593.74
6468.86
6753.37
6905.99
6776.49
6501.13
6476.28
6459.77
6564.56
6959.95
7099.87
6935.65
6773.59
6698.94
6996.49
6665.35
6759.45
6654.49
6938.87
7175.18
7406.9
7122.63
7084.91
7047.75
6978.56
7018.51
6981.53
7062.36
6609.17
6433.83
6681.74
6731.39
7064.39
7434.37
7356.02
7006.26
6809.74
7031.62
7085.84
6996.02
7278.02
7343.13
7148.41
6918.55
7248.71
7065.72
7317.03
7348.06
7527.43
7315.65
7342.31
7125.93
7173.94
7415.9
7458.17
8097.92
7987.09
8409.66
7592.8
6897.75
6919.45
7272.17
7556.84
7399.61
7664.4
7256.48
7236.88
7358.4
7196.38
7089.13
7258.17
6952.56
7021.68
6946.62
7388.86
7362.27
7439.42
7214.55
7455.32
7503.44
7381.52
7643.07
7843.43
7326.64
7081.89
7480.1
7717.26
7436.54
8025.87
7322.73
7533.07
7777.59
7947.37
7272.13
7348.91
7466.85
8101.13
7983.67
7817.58
7454.57
7968.85
7726.62
7522.97
7789.57
8046.77
7913.35
8388.46
8558.92
8345.14
8251.82
7920.76
7657.02
7314
7931.43
8071.3
8479.99
8346.96
8299.28
9574.41
12283.9
16114.2
17100.1
12203.4
7752.57
6576.5
5892.75
5555.74
5401.44
5352.02
5615.54
5929.02
5673.68
5587.15
5937.77
6026.23
5858.21
5691.5
6144.27
5691.33
5417.48
5273.52
5402.8
5369.09
5317.37
4896.02
5053.24
5104.39
4693.3
4767.42
5109.4
5151.5
6156.71
7594.27
8023.59
8726.65
7998.13
6550.19
5520.74
6662.62
9485.4
9251.54
4883.65
2204.89
1745.42
1624.44
1620
1529.31
1433.28
1445.69
1488.45
1410.25
1221.92
1261.24
1268.15
1078.27
1141.64
1166.53
1195.57
1373.64
1495.81
1309.29
1645.28
1806.56
2077.56
2390.18
2829.17
3145.28
3378.66
3374.69
2433.87
1654.42
1169.62
1052.64
822.528
759.785
762.064
834.402
839.909
889.014
1201.44
1327.82
1638.34
1912.91
1713.02
1821.52
1751.19
1321.72
1181.31
749.546
520.199
181.529
23.5611
end of experiment