File: examples/vms/data_analysis/FeO_analyzed.vms
VAMAS Surface Chemical Analysis Standard Data Transfer Format 1988 May 4
Not Specified
Not Specified
Not Specified
Not Specified
5
Casa Info Follows CasaXPS Version 2.3.25PR1.0
0
Created by SpecsLab Prodigy, Version 4.54.1-r81613
SourceAnalyserAngle: Not Specified
CasaRowLabel:FeO
NORM
IRREGULAR
0
1
Exp Variable
d
0
0
0
0
1
Fe 2p
FeO
0
0
0
0
0
0
0
17
Casa Info Follows
0
1
annot comps v2315 ExArea ExConcentration Display 0.0897959 0.140594 RGB(0,0,255) Font(35,34,700,0,Arial)

1
CASA region (*Fe 2p*) (*U 3 Tougaard*) 737.52081 786.7632 16.42 2 0 0 335.44588 551 436 3 (*Fe 2p*) 55.8458 0 16.42
4
CASA comp (*Fe 2p*) (*LF(0.54,10,80,100,6)*) Area 63507.374 1e-020 6383903.5 -1 1 MFWHM 3.8576238 1.07 26.75 -1 1 Position 777.56313 738.01 782.59919 -1 1 RSF 16.42 MASS 55.8458 INDEX 0 (*Fe 2p*) CONST (**) UNCORRECTEDRSF 16.42
CASA comp (*Fe 2p*) (*SGL(30)*) Area 35837.064 1e-020 6383903.5 -1 1 MFWHM 8 1.07 8 -1 1 Position 770.61 770.61 772.61 -1 1 RSF 16.42 MASS 55.8458 INDEX 1 (*Fe 2p*) CONST (**) UNCORRECTEDRSF 16.42
CASA comp (*Fe 2p*) (*LF(0.54,10,80,100,6)*) Area 49042.126 1e-020 6383903.5 -1 1 MFWHM 4.8730051 1.07 26.75 -1 1 Position 764.48234 738.01 782.59919 -1 -13 RSF 16.42 MASS 55.8458 INDEX 0 (*Fe 2p*) CONST (**) UNCORRECTEDRSF 16.42
CASA comp (*Fe 2p*) (*SGL(30)*) Area 17705.155 1e-020 6383903.5 -1 1 MFWHM 7.8295407 1.07 8 -1 1 Position 756.72212 756.11 759.61 -1 1 RSF 16.42 MASS 55.8458 INDEX 1 (*Fe 2p*) CONST (**) UNCORRECTEDRSF 16.42
FeO.vms Dir:C:\Users\pielsticker\Desktop\fe references\
Fe2p_FeO.vms Dir:C:\Users\pielsticker\Desktop\fe references\

Sum of 2 spectra in column containing 2 scans
C:\Users\pielsticker\Lukas\MPI-CEC\Projects\Reference data\Fe\iron references\FeO_analyzed.vms
XPS
0
Al
1486.61
1e+037
1e+037
1e+037
1e+037
1e+037
FAT
1e+037
1e+037
1e+037
1e+037
1e+037
1e+037
1e+037
1e+037
Fe
2p
-1
3
Kinetic Energy
eV
Intensity
d
transmission
d
pulse counting
2
1
1e+037
1e+037
1e+037
1e+037
3
MFP Exponent
d
0
ESCAPE DEPTH TYPE
d
1
PROPAGATION_CONVERGED
d
1
1
0
12516.9
12304.9
12369
12450
12465.5
12320.6
12346.7
12383.2
12513.4
12351.3
12198.3
12262.2
12152.7
12243.7
12616.7
12386.5
12306.9
12352.2
12407.5
12473.1
12388.2
12364.1
12277.8
12322.9
12392.7
12188.7
12432.9
12610.8
12465.2
12491.2
12319.5
12493.8
12406.7
12436.3
12383.4
12482.3
12469.8
12457.7
12483.2
12611.2
12760.7
12650.8
12436.7
12400.7
12687.8
12413.3
12635.2
12572.2
12579.8
12652
12536.5
12567.8
12453
12589.7
12634.8
12607.3
12402
12652.9
12767.1
12713.4
12668.3
12691.2
12508.5
12672.5
12757.7
12844.8
12750.4
12704.5
12826.6
12687.9
12758.8
12725.8
12640.4
12572.6
12803.5
12703.2
12853.4
12812.2
12946
12838.3
12724.5
12550.3
12770.9
12824.9
12795.2
12958.8
12704.1
12783.4
12876.2
13044.7
12882.8
12682
12785.5
12936.7
12808.2
13128.9
12956.7
12876.2
12665.8
12897.7
13040.8
13033.6
12992.5
12943.4
13196.6
13060
12958.6
13018.2
13012.4
12988.1
12896.1
13255.4
13038.5
13124.7
12927.3
12860.3
12980.3
13091.5
12880.7
12880.9
13228.9
13180.5
13122.1
13118.2
12837.5
12978.4
13010
13047.1
12923.5
12874.9
13033.7
13099.7
12987.6
12998.6
12959.8
13056.1
13097.8
13245.7
13131.2
13014.6
13164
12963.4
12886.1
12848.7
12920.7
13044.7
12997.3
13317.7
13163.1
13052
13172.7
12954
13117.5
13140.9
13145
13080.4
13087.7
12773.2
12953
12922.9
12886.2
12950.9
12997.8
13005.1
12908.9
12999.1
12929.2
12911.3
13072.4
12755.2
12730.1
13079.3
13014.4
12766.7
12926.6
13014.8
12823
12810.3
12737.6
12904.4
13023.3
12866
12932.8
13000.6
12787
12784.3
12874.9
12841.2
12910.5
12721.9
12994.9
12951
12976.3
12861.1
12740.7
12774.4
12992.3
12891.5
12726.7
12682.2
12783.9
12731.3
12794.6
12876.6
13003.4
12916.6
12765.4
12953.1
12731.9
12749.2
12884.7
12787.2
13017.8
12823
12719.8
12917.5
12917.7
12942.3
12842.5
12849.9
12968.3
12997.5
12827.3
12821.4
12747.8
12965.2
12901
12896.4
12985.6
13088.2
13058.7
12841.4
13066.2
12786.6
12743.5
12944
13008.3
12765.8
12860.4
12739.3
12960.1
13034.2
12932.3
13067.2
13256.1
13125.5
13045.4
13171.7
13075.9
12884
13126.1
13105.4
12840.7
13035.2
13104.2
13297.1
13058.3
13010.3
13023
13046.5
13290.3
13354.7
13450.3
13420.1
13265.2
13245.1
13187.3
13285.9
13286.6
13285.1
13485.2
13523.7
13457.1
13244.5
13506.7
13510.7
13321.1
13304.3
13694.5
13509.6
13267.1
13298.8
13676.3
13630.4
13596.4
13570
13605.9
13631.7
13825.4
13755.3
13546.9
13765.9
13603.5
13619
13580.3
13790
13557.5
13694.4
13692.2
13601.3
13791.5
13725.4
13904.3
13596.5
13792
13725.3
13753.4
13951.4
13681.8
13637.5
14136.5
13974.2
13928.6
14065.4
13912.1
14115.3
14026.9
14286.5
14188.4
14091.2
14104.3
14156.9
14273.7
14298.8
14362.7
14402.8
14209.2
14111.4
14152.2
14099.3
14219.2
14205.2
14257.7
14460
14435.9
14327.7
14528.5
14414
14411.2
14640.6
14429.8
14564.2
14571.8
14386.1
14393
14860.7
14677.9
14848.8
14827.7
14716.3
14834.7
14582.6
14817.2
15010
15041
14939.9
15072.5
15107.6
14941.6
15114.2
15121.4
14901.6
15160
15100.3
15118.1
15230.8
15377.2
15319.3
15218.5
15256.3
15434.9
15717.8
15477.9
15593.4
15710.9
15542.8
15588.4
15578.8
15562
15827.4
15767.1
15941.5
16151.1
16079.8
16093.3
16028.5
16110.8
16108
15975
16048.5
15936.6
15938.7
15932.1
16057.2
15949.2
16312.5
16205.5
16132.1
16202.6
16391.8
16311.4
16249.9
16345.8
16458.9
16478.1
16376
16457.2
16225
16261.8
16337.4
16275.6
16103.7
16309.2
16450.3
16511.3
16248.8
16385.1
16349.4
16472
16196.4
16499.7
16441.8
16223
16327.9
16391.5
16395.5
16304.3
16293.4
16191.3
16150
16364.9
16395.1
16266.8
16296.8
16367.6
16343.4
16090.4
16014.2
16342.8
16296.2
16132.7
16028.1
16192.7
16137.3
16255.3
16097.3
15955.2
16129.3
16244.6
16073.4
16416.4
16401.7
16306
16189
16226.9
16376.7
16174.8
16299.9
16107
16149.3
16255.6
16262.3
16467.3
16698.1
16391.6
16408.4
16688.4
16561.9
16644.1
16645.9
16969.2
16883.9
17071.4
16733.9
17005.8
17032.5
16952.2
16846.8
17193.7
16985.2
17263.4
17701.1
17448.8
17381.6
17362.6
17615
17594.2
17669.6
17945.2
17880.6
17829.9
17546.6
18040.2
18053.5
18005.7
18250
18418.1
18566.8
18537.3
18549.1
18552.1
18761.4
18876.1
19047.9
19145.4
19027.3
19185.2
19214.7
19591.6
19476.6
19602.5
19502.2
20002.6
19571
19544.8
20063.7
20046.6
20005.1
20200.2
20232.5
19991
20322.5
20339.3
20260.1
20527.1
20704.4
20726.7
20185.3
20423.1
20770.2
20427.2
20380.1
20849.3
20773.5
20410.5
20882.9
20793.5
20891
20496.2
20782.3
20548.3
20542.8
20267.2
19899.4
20429.4
20345.9
20187.4
20180.6
20198.2
20113.8
19892.7
19599.3
19560.3
19381.3
19546.7
19194.3
19162.3
18867.9
18733.1
18796.4
18695.7
18560.4
18278.4
18194.4
17935.1
17720.4
17600.1
17581.7
17289
17169.1
17238.2
16918.7
16745.1
16886.4
16525.5
16268.2
15953.5
15986.2
15872.4
15818
15675.4
15532.5
15191.5
15218.2
14987.2
14856.6
14785.6
14703
14633.2
14271.1
14202.3
14409.9
14335.3
13962.9
13982.3
14156.2
14063
13847.5
13960.8
13869.1
13717.4
13725.6
13555.1
13777.9
13708.4
13748.8
13634.6
13456
13371.9
13555.2
13511.6
13346.7
13360.1
13184.4
13283
13282.8
13286.6
13182.6
13356.3
13274
13215.7
13072
13140.5
13174.1
13185.7
13176.2
13054.1
13210.6
13120.2
13156.4
13326.1
13173.8
13368.2
13357.7
13401.4
13293.5
13388.8
13283.4
13499.7
13430.2
13420.3
13526.8
13577.9
13587.8
13830
13779.3
13794.6
13820.5
13971.8
14069.2
14054
14219.9
14010.2
14211.5
14420.6
14066
13957.8
14342.5
14375.2
14280.3
14398.4
14289.3
14627.6
14701.1
14561.4
14622.6
14628.8
14912.9
15125.9
14877.4
15113.5
15141.4
15172
15140.2
15080.2
15074.1
14933.2
15215.2
15170.9
15172.7
15164
15330.5
15205.1
15282
15483.9
15490.4
15407.3
15258.2
15311.9
15383.6
15490.6
15282
15465.1
15518.5
15486.8
15428.7
15456
15380.5
15544.4
15503
15469.2
15523.9
15651.7
15414.1
15521.2
15657
15705.5
15526.3
15623.2
15679.8
15772.6
15796.8
15769.6
15643.5
15575.7
15635.7
15690.6
15683.5
16006.6
15924.6
15928.3
16164.6
16141.6
16276.1
16174.2
16104.7
16126.6
16395.9
16390.8
16571.5
16600.6
16296.2
16778.1
16726.6
16784.5
16890.4
16935.7
17105.4
17382.7
17521
17623.2
17540.5
17485.7
17757
17598.1
17991
17973.5
18120.8
18173.6
18432.3
18740.3
18550.7
18674.1
18782.4
18907.6
19271.4
19542.4
19254.4
19689.8
19510.5
19778
19974.4
19844.1
20216.7
19887
20442.3
20608.1
20924.5
20772.2
21059.9
21230.5
21404
21393.9
21362.5
21532
21736.9
22004.6
21958.5
22078.6
22193.9
22285.8
22246.4
22666
22693
22886
22911.9
22899.5
23176.2
23335.1
23589.3
23708.7
23646.6
23720.5
23965.4
23680.5
23947.8
23878.8
23941.4
24040.7
23511.5
23963.2
23827.1
23687
23664.4
23636.3
23313
23263.8
23251.9
23218.6
23107.2
22836.1
22591
22608.6
22433.6
22594
22138.9
22024.4
21632.8
21459.1
21257.7
21103.8
20765.5
20260.3
20221.6
19808.1
19361.3
18805.3
18595.3
17972.3
17765.6
17233.2
16943.6
16605
16114.3
15603.5
15338.7
14829.8
14482
13869
13601.8
12828.7
12554.3
12083.8
11907.3
11237.6
10979.9
10182.7
10035.7
9574.43
9309.98
8942.98
8613.5
8340.97
8089.68
7690.45
7516.83
7191.47
6880.43
6558.2
6313.38
6258.27
6130.52
5774.53
5731.43
5540.15
5346.97
5182.35
5032.4
4921.68
4843.57
4732.52
4629.25
4578.65
4366.28
4282.45
4277.48
4081.87
4036.97
4032
3871.15
3874.02
3739.6
3736.88
3622.93
3575.98
3565.67
3432.25
3583.9
3462.7
3468.55
3423.55
3310.16
3319.82
3360.78
3308.87
3228.51
3286.56
3278.25
3281.06
3268.83
3260.76
3211.46
3167.2
3202.6
3228.5
3149.82
3166.4
3092.8
3073.05
3210.75
3183.55
3165.56
3118.33
3079.63
3101.82
3034.35
3031.89
3126.93
3042.8
3115.89
3077.38
2954.17
3041.47
2995.47
2946.74
2955.48
2942.29
3089.31
3031.14
3065.58
3041.33
2980.48
2976.6
2978.29
2878.97
2952.59
3053.91
3012.8
2883.61
2895.57
2930.39
2868.61
2996.58
3009.34
2924.31
3043.32
3120.75
3096.82
3000.82
3032.17
2949.81
2950.1
3008.83
2908.96
3019.26
2950.69
2942.44
2956.81
2860.81
2938.4
3018.89
3099.79
2867.95
2903.12
2880.85
2923.69
2906.75
2925.01
2938.65
2910.88
2867.33
2920.02
2972.48
3013.76
2839.56
2940.42
2936.88
2841.67
2892.58
2959.06
2931.21
2913.27
2927.07
2879.25
2939.09
2895.84
2983.45
3022.02
2999.13
3009.35
2934.12
2892.08
2886.24
2985.36
2912.28
2889.37
2942.78
2915.88
2958
3029.28
2952.85
2946.24
2886.53
3017.85
2936.63
2876.9
2884.39
2955.08
2891.89
2958.88
2913.19
2879.65
3010.42
2843.68
2922.04
2924.48
2833.76
2866.48
2836.76
2930.34
2881.52
2823.53
2725.18
2879.13
2854.7
2860.83
3002.67
2948.91
2868.86
2828.14
2876.37
2965.84
2972.42
2947.95
2823.05
2835.78
2983.42
2886.08
2848.75
2915.24
2921.82
2781.38
2938.45
2854.48
2868.32
2905.01
2904.27
2924.27
2813.72
2857.34
2920.51
2905.8
2875.74
2967.4
2915.56
2963.48
2903.83
2914.29
2955.2
2909.1
3007.25
2946.47
2919.68
2953.82
2874.5
2870.11
2786.42
2954.97
2895.57
2915.76
2908.66
2867.31
2839.09
2926.44
2867.5
2932.28
3012.78
2918.23
3005.4
2912.58
2942.93
2883.19
2997.4
2884.17
2880.33
2804.35
2861.69
2844.27
2894.57
2894.03
2847.9
2820.27
2805.18
2882.79
2966.1
2852.17
2804.32
2859.23
2921.61
3025.18
2916.77
2863.34
2846.63
2921.08
2861.67
2805.36
2873.44
2925.43
2925.11
2942.25
2952.45
2938.68
2878.14
2891.44
2828.32
2859.94
2854.2
2889.02
2901.12
2954.64
2884.3
2.67321
end of experiment